Using TensorFlow backend.
/home/rice/jmc32/anaconda2/envs/tensorflow-gpu/lib/python2.7/site-packages/keras/models.py:981: UserWarning: The `nb_epoch` argument in `fit` has been renamed `epochs`.
  warnings.warn('The `nb_epoch` argument in `fit` '
2018-07-06 15:03:52.819309: I tensorflow/core/platform/cpu_feature_guard.cc:140] Your CPU supports instructions that this TensorFlow binary was not compiled to use: SSE4.1 SSE4.2 AVX AVX2 FMA
2018-07-06 15:03:53.345660: I tensorflow/core/common_runtime/gpu/gpu_device.cc:1356] Found device 0 with properties: 
name: Tesla P100-PCIE-16GB major: 6 minor: 0 memoryClockRate(GHz): 1.3285
pciBusID: 0000:16:00.0
totalMemory: 15.90GiB freeMemory: 15.61GiB
2018-07-06 15:03:53.608080: I tensorflow/core/common_runtime/gpu/gpu_device.cc:1356] Found device 1 with properties: 
name: Tesla P100-PCIE-16GB major: 6 minor: 0 memoryClockRate(GHz): 1.3285
pciBusID: 0000:19:00.0
totalMemory: 15.90GiB freeMemory: 15.61GiB
2018-07-06 15:03:53.619283: I tensorflow/core/common_runtime/gpu/gpu_device.cc:1435] Adding visible gpu devices: 0, 1
2018-07-06 15:03:58.152309: I tensorflow/core/common_runtime/gpu/gpu_device.cc:923] Device interconnect StreamExecutor with strength 1 edge matrix:
2018-07-06 15:03:58.152699: I tensorflow/core/common_runtime/gpu/gpu_device.cc:929]      0 1 
2018-07-06 15:03:58.152721: I tensorflow/core/common_runtime/gpu/gpu_device.cc:942] 0:   N Y 
2018-07-06 15:03:58.152730: I tensorflow/core/common_runtime/gpu/gpu_device.cc:942] 1:   Y N 
2018-07-06 15:03:58.153680: I tensorflow/core/common_runtime/gpu/gpu_device.cc:1053] Created TensorFlow device (/job:localhost/replica:0/task:0/device:GPU:0 with 15135 MB memory) -> physical GPU (device: 0, name: Tesla P100-PCIE-16GB, pci bus id: 0000:16:00.0, compute capability: 6.0)
2018-07-06 15:03:58.339492: I tensorflow/core/common_runtime/gpu/gpu_device.cc:1053] Created TensorFlow device (/job:localhost/replica:0/task:0/device:GPU:1 with 15135 MB memory) -> physical GPU (device: 1, name: Tesla P100-PCIE-16GB, pci bus id: 0000:19:00.0, compute capability: 6.0)
(100000, 7)
(900000, 7)
Traceback (most recent call last):
  File "/home/rice/jmc32/DNN_for_Pt_Assignment-master/DNN_Hyperparameters/TestandTrain1NetConfig1AI.py", line 121, in <module>
    model_predictions = model.predict(y_test)
  File "/home/rice/jmc32/anaconda2/envs/tensorflow-gpu/lib/python2.7/site-packages/keras/wrappers/scikit_learn.py", line 228, in predict
    proba = self.model.predict(x, **kwargs)
  File "/home/rice/jmc32/anaconda2/envs/tensorflow-gpu/lib/python2.7/site-packages/keras/models.py", line 1064, in predict
    steps=steps)
  File "/home/rice/jmc32/anaconda2/envs/tensorflow-gpu/lib/python2.7/site-packages/keras/engine/training.py", line 1817, in predict
    check_batch_axis=False)
  File "/home/rice/jmc32/anaconda2/envs/tensorflow-gpu/lib/python2.7/site-packages/keras/engine/training.py", line 123, in _standardize_input_data
    str(data_shape))
ValueError: Error when checking : expected dense_1_input to have shape (7,) but got array with shape (1,)
('True negative total is ', 43613, 'out of', 100000)
('True positive total is ', 29252)
('False negative total is ', 26946)
('False positive total is ', 189)
('Any missed ones? ', 0)
