Using TensorFlow backend.
2018-06-08 14:03:27.641250: I tensorflow/core/platform/cpu_feature_guard.cc:140] Your CPU supports instructions that this TensorFlow binary was not compiled to use: AVX2 FMA
Traceback (most recent call last):
  File "/home/rice/jmc32/DNN_for_Pt_Assignment-master/DNN_Hyperparameters/GPU_Check.py", line 8, in <module>
    print (sess.run(c))
  File "/home/rice/jmc32/anaconda2/envs/tensorflow/lib/python2.7/site-packages/tensorflow/python/client/session.py", line 900, in run
    run_metadata_ptr)
  File "/home/rice/jmc32/anaconda2/envs/tensorflow/lib/python2.7/site-packages/tensorflow/python/client/session.py", line 1135, in _run
    feed_dict_tensor, options, run_metadata)
  File "/home/rice/jmc32/anaconda2/envs/tensorflow/lib/python2.7/site-packages/tensorflow/python/client/session.py", line 1316, in _do_run
    run_metadata)
  File "/home/rice/jmc32/anaconda2/envs/tensorflow/lib/python2.7/site-packages/tensorflow/python/client/session.py", line 1335, in _do_call
    raise type(e)(node_def, op, message)
tensorflow.python.framework.errors_impl.InvalidArgumentError: Cannot assign a device for operation 'MatMul': Operation was explicitly assigned to /device:GPU:0 but available devices are [ /job:localhost/replica:0/task:0/device:CPU:0 ]. Make sure the device specification refers to a valid device.
	 [[Node: MatMul = MatMul[T=DT_FLOAT, transpose_a=false, transpose_b=false, _device="/device:GPU:0"](a, b)]]

Caused by op u'MatMul', defined at:
  File "/home/rice/jmc32/DNN_for_Pt_Assignment-master/DNN_Hyperparameters/GPU_Check.py", line 5, in <module>
    c = tf.matmul(a, b)
  File "/home/rice/jmc32/anaconda2/envs/tensorflow/lib/python2.7/site-packages/tensorflow/python/ops/math_ops.py", line 2122, in matmul
    a, b, transpose_a=transpose_a, transpose_b=transpose_b, name=name)
  File "/home/rice/jmc32/anaconda2/envs/tensorflow/lib/python2.7/site-packages/tensorflow/python/ops/gen_math_ops.py", line 4279, in mat_mul
    name=name)
  File "/home/rice/jmc32/anaconda2/envs/tensorflow/lib/python2.7/site-packages/tensorflow/python/framework/op_def_library.py", line 787, in _apply_op_helper
    op_def=op_def)
  File "/home/rice/jmc32/anaconda2/envs/tensorflow/lib/python2.7/site-packages/tensorflow/python/framework/ops.py", line 3392, in create_op
    op_def=op_def)
  File "/home/rice/jmc32/anaconda2/envs/tensorflow/lib/python2.7/site-packages/tensorflow/python/framework/ops.py", line 1718, in __init__
    self._traceback = self._graph._extract_stack()  # pylint: disable=protected-access

InvalidArgumentError (see above for traceback): Cannot assign a device for operation 'MatMul': Operation was explicitly assigned to /device:GPU:0 but available devices are [ /job:localhost/replica:0/task:0/device:CPU:0 ]. Make sure the device specification refers to a valid device.
	 [[Node: MatMul = MatMul[T=DT_FLOAT, transpose_a=false, transpose_b=false, _device="/device:GPU:0"](a, b)]]

Using TensorFlow backend.
3
Seed value is 44
MaxAbs

Traceback (most recent call last):
  File "/home/rice/jmc32/DNN_for_Pt_Assignment-master/DNN_Hyperparameters/TestandTrain1NetConfig1AI.py", line 115, in <module>
    history = model.fit(X_train,Y_train, nb_epoch=number_of_epochs, batch_size = set_batch_size)
  File "/home/rice/jmc32/anaconda2/envs/tensorflow/lib/python2.7/site-packages/keras/wrappers/scikit_learn.py", line 209, in fit
    return super(KerasClassifier, self).fit(x, y, **kwargs)
  File "/home/rice/jmc32/anaconda2/envs/tensorflow/lib/python2.7/site-packages/keras/wrappers/scikit_learn.py", line 140, in fit
    self.model = self.build_fn(**self.filter_sk_params(self.build_fn))
  File "/home/rice/jmc32/DNN_for_Pt_Assignment-master/DNN_Hyperparameters/macros_AWS.py", line 61, in create_model
    input_model.compile(loss='binary_crossentropy', optimizer='SDG', metrics=['accuracy'])
  File "/home/rice/jmc32/anaconda2/envs/tensorflow/lib/python2.7/site-packages/keras/models.py", line 824, in compile
    **kwargs)
  File "/home/rice/jmc32/anaconda2/envs/tensorflow/lib/python2.7/site-packages/keras/engine/training.py", line 604, in compile
    self.optimizer = optimizers.get(optimizer)
  File "/home/rice/jmc32/anaconda2/envs/tensorflow/lib/python2.7/site-packages/keras/optimizers.py", line 763, in get
    return deserialize(config)
  File "/home/rice/jmc32/anaconda2/envs/tensorflow/lib/python2.7/site-packages/keras/optimizers.py", line 735, in deserialize
    printable_module_name='optimizer')
  File "/home/rice/jmc32/anaconda2/envs/tensorflow/lib/python2.7/site-packages/keras/utils/generic_utils.py", line 138, in deserialize_keras_object
    ': ' + class_name)
ValueError: Unknown optimizer: SDG
('True negative total is ', 40019, 'out of', 100000)
('True positive total is ', 53741)
('False negative total is ', 2586)
('False positive total is ', 3654)
('Any missed ones? ', 0)
